<?xml version="1.0" ?>
<!-- =================================================================================== -->
<!-- |    This document was autogenerated by xacro from med14.urdf.xacro               | -->
<!-- |    EDITING THIS FILE BY HAND IS NOT RECOMMENDED                                 | -->
<!-- =================================================================================== -->
<!-- top level -->
<robot name="med14">
	<material name="orange">
		<color rgba="1.0 0.42 0.04 1.0"/>
	</material>
	<material name="white">
		<color rgba="1.0 1.0 1.0 1.0"/>
	</material>
	<material name="silver">
		<color rgba="0.7 0.7 0.7 1.0"/>
	</material>
	<!-- fix to world -->
	<link name="world"/>
	<!--joint between {parent} and link_0-->
	<joint name="world_lbr_joint" type="fixed">
		<parent link="world"/>
		<child link="lbr_link_0"/>
	</joint>
	<link name="lbr_link_0">
		<inertial>
			<origin rpy="0 0 0" xyz="-0.0018642104260720833 -9.120393625716289e-09 0.07751683665104403"/>
			<mass value="8.146350"/>
			<inertia ixx="0.044603" ixy="-0.000000" ixz="-0.000788" iyy="0.045465" iyz="0.000000" izz="0.061903"/>
		</inertial>
		<visual>
			<origin rpy="0 0 0" xyz="0 0 0"/>
			<geometry>
				<mesh filename="meshes/med14/visual/link_0.stl"/>
			</geometry>
			<material name="white"/>
		</visual>
		<collision>
			<origin rpy="0 0 0" xyz="0 0 0"/>
			<geometry>
				<mesh filename="meshes/med14/collision/link_0.stl"/>
			</geometry>
		</collision>
	</link>
	<joint name="lbr_joint_0" type="revolute">
		<origin rpy="0 0 0" xyz="0.0 0.0 0.147"/>
		<parent link="lbr_link_0"/>
		<child link="lbr_link_1"/>
		<axis xyz="0.0 0.0 1.0"/>
		<limit effort="300" lower="-2.9670597283903604" upper="2.9670597283903604" velocity="10"/>
		<dynamics damping="10.0" friction="0.1"/>
	</joint>
	<link name="lbr_link_1">
		<inertial>
			<origin rpy="0 0 0" xyz="9.307232415315581e-08 -0.033795431550791004 0.13240370669453896"/>
			<mass value="5.591386"/>
			<inertia ixx="0.044885" ixy="-0.000000" ixz="-0.000000" iyy="0.045283" iyz="0.006703" izz="0.016775"/>
		</inertial>
		<visual>
			<origin rpy="0 0 0" xyz="-0.0 -0.0 -0.147"/>
			<geometry>
				<mesh filename="meshes/med14/visual/link_1.stl"/>
			</geometry>
			<material name="white"/>
		</visual>
		<collision>
			<origin rpy="0 0 0" xyz="-0.0 -0.0 -0.147"/>
			<geometry>
				<mesh filename="meshes/med14/collision/link_1.stl"/>
			</geometry>
		</collision>
	</link>
	<joint name="lbr_joint_1" type="revolute">
		<origin rpy="0 0 0" xyz="0.0 -0.01 0.2125"/>
		<parent link="lbr_link_1"/>
		<child link="lbr_link_2"/>
		<axis xyz="0.0 1.0 0.0"/>
		<limit effort="300" lower="-2.0943951023931953" upper="2.0943951023931953" velocity="10"/>
		<dynamics damping="10.0" friction="0.1"/>
	</joint>
	<link name="lbr_link_2">
		<inertial>
			<origin rpy="0 0 0" xyz="0.0001358226533474577 0.0475476440926152 0.07632205850106144"/>
			<mass value="6.013539"/>
			<inertia ixx="0.058332" ixy="-0.000035" ixz="0.000059" iyy="0.057063" iyz="0.010606" izz="0.017466"/>
		</inertial>
		<visual>
			<origin rpy="0 0 0" xyz="-0.0 0.01 -0.3595"/>
			<geometry>
				<mesh filename="meshes/med14/visual/link_2.stl"/>
			</geometry>
			<material name="white"/>
		</visual>
		<collision>
			<origin rpy="0 0 0" xyz="-0.0 0.01 -0.3595"/>
			<geometry>
				<mesh filename="meshes/med14/collision/link_2.stl"/>
			</geometry>
		</collision>
	</link>
	<joint name="lbr_joint_2" type="revolute">
		<origin rpy="0 0 0" xyz="-0.0 0.01 0.228"/>
		<parent link="lbr_link_2"/>
		<child link="lbr_link_3"/>
		<axis xyz="0.0 0.0 1.0"/>
		<limit effort="300" lower="-2.9670597283903604" upper="2.9670597283903604" velocity="10"/>
		<dynamics damping="10.0" friction="0.1"/>
	</joint>
	<link name="lbr_link_3">
		<inertial>
			<origin rpy="0 0 0" xyz="5.689213978259012e-08 0.03491265072974692 0.12310820658934007"/>
			<mass value="3.658768"/>
			<inertia ixx="0.022960" ixy="-0.000000" ixz="0.000000" iyy="0.021913" iyz="-0.004065" izz="0.008140"/>
		</inertial>
		<visual>
			<origin rpy="0 0 0" xyz="0.0 -0.0 -0.5875"/>
			<geometry>
				<mesh filename="meshes/med14/visual/link_3.stl"/>
			</geometry>
			<material name="white"/>
		</visual>
		<collision>
			<origin rpy="0 0 0" xyz="0.0 -0.0 -0.5875"/>
			<geometry>
				<mesh filename="meshes/med14/collision/link_3.stl"/>
			</geometry>
		</collision>
	</link>
	<joint name="lbr_joint_3" type="revolute">
		<origin rpy="0 0 0" xyz="0.0 0.0105 0.192"/>
		<parent link="lbr_link_3"/>
		<child link="lbr_link_4"/>
		<axis xyz="0.0 -1.0 0.0"/>
		<limit effort="300" lower="-2.0943951023931953" upper="2.0943951023931953" velocity="10"/>
		<dynamics damping="10.0" friction="0.1"/>
	</joint>
	<link name="lbr_link_4">
		<inertial>
			<origin rpy="0 0 0" xyz="-3.025185496951432e-08 -0.03979329512420171 0.08694364647762443"/>
			<mass value="4.358282"/>
			<inertia ixx="0.034259" ixy="-0.000000" ixz="-0.000000" iyy="0.032514" iyz="-0.006365" izz="0.010447"/>
		</inertial>
		<visual>
			<origin rpy="0 0 0" xyz="0.0 -0.0105 -0.7795"/>
			<geometry>
				<mesh filename="meshes/med14/visual/link_4.stl"/>
			</geometry>
			<material name="white"/>
		</visual>
		<collision>
			<origin rpy="0 0 0" xyz="0.0 -0.0105 -0.7795"/>
			<geometry>
				<mesh filename="meshes/med14/collision/link_4.stl"/>
			</geometry>
		</collision>
	</link>
	<joint name="lbr_joint_4" type="revolute">
		<origin rpy="0 0 0" xyz="0.0 -0.0105 0.2075"/>
		<parent link="lbr_link_4"/>
		<child link="lbr_link_5"/>
		<axis xyz="0.0 0.0 1.0"/>
		<limit effort="300" lower="-2.9670597283903604" upper="2.9670597283903604" velocity="10"/>
		<dynamics damping="10.0" friction="0.1"/>
	</joint>
	<link name="lbr_link_5">
		<inertial>
			<origin rpy="0 0 0" xyz="3.8871741664391765e-08 -0.029824284088761824 0.07626701716135809"/>
			<mass value="1.652994"/>
			<inertia ixx="0.009172" ixy="0.000000" ixz="-0.000000" iyy="0.007714" iyz="0.003033" izz="0.004159"/>
		</inertial>
		<visual>
			<origin rpy="0 0 0" xyz="-0.0 0.0 -0.987"/>
			<geometry>
				<mesh filename="meshes/med14/visual/link_5.stl"/>
			</geometry>
			<material name="white"/>
		</visual>
		<collision>
			<origin rpy="0 0 0" xyz="-0.0 0.0 -0.987"/>
			<geometry>
				<mesh filename="meshes/med14/collision/link_5.stl"/>
			</geometry>
		</collision>
	</link>
	<joint name="lbr_joint_5" type="revolute">
		<origin rpy="0 0 0" xyz="0.0 -0.0707 0.1925"/>
		<parent link="lbr_link_5"/>
		<child link="lbr_link_6"/>
		<axis xyz="0.0 1.0 0.0"/>
		<limit effort="300" lower="-2.0943951023931953" upper="2.0943951023931953" velocity="10"/>
		<dynamics damping="10.0" friction="0.1"/>
	</joint>
	<link name="lbr_link_6">
		<inertial>
			<origin rpy="0 0 0" xyz="-7.073221484902805e-07 0.07101990943401978 0.004952526180380223"/>
			<mass value="2.598208"/>
			<inertia ixx="0.007640" ixy="-0.000000" ixz="0.000000" iyy="0.007355" iyz="0.000336" izz="0.005004"/>
		</inertial>
		<visual>
			<origin rpy="0 0 0" xyz="-0.0 0.0707 -1.1795"/>
			<geometry>
				<mesh filename="meshes/med14/visual/link_6.stl"/>
			</geometry>
			<material name="white"/>
		</visual>
		<collision>
			<origin rpy="0 0 0" xyz="-0.0 0.0707 -1.1795"/>
			<geometry>
				<mesh filename="meshes/med14/collision/link_6.stl"/>
			</geometry>
		</collision>
	</link>
	<joint name="lbr_joint_6" type="revolute">
		<origin rpy="0 0 0" xyz="0.0 0.0707 0.091"/>
		<parent link="lbr_link_6"/>
		<child link="lbr_link_7"/>
		<axis xyz="0.0 0.0 1.0"/>
		<limit effort="300" lower="-3.0543261909900763" upper="3.0543261909900763" velocity="10"/>
		<dynamics damping="10.0" friction="0.1"/>
	</joint>
	<link name="lbr_link_7">
		<inertial>
			<origin rpy="0 0 0" xyz="3.121827460016089e-06 -1.635815563460264e-06 0.0137822955218736"/>
			<mass value="0.280472"/>
			<inertia ixx="0.000185" ixy="0.000000" ixz="-0.000000" iyy="0.000185" iyz="0.000000" izz="0.000323"/>
		</inertial>
		<visual>
			<origin rpy="0 0 0" xyz="-0.0 -0.0 -1.2705"/>
			<geometry>
				<mesh filename="meshes/med14/visual/link_7.stl"/>
			</geometry>
			<material name="silver"/>
		</visual>
		<collision>
			<origin rpy="0 0 0" xyz="-0.0 -0.0 -1.2705"/>
			<geometry>
				<mesh filename="meshes/med14/collision/link_7.stl"/>
			</geometry>
		</collision>
	</link>
	<joint name="lbr_joint_ee" type="fixed">
		<parent link="lbr_link_7"/>
		<child link="lbr_link_ee"/>
		<origin rpy="0 0 0" xyz="0 0 0.035"/>
	</joint>
	<link name="lbr_link_ee">
        </link>
</robot>
